response@ChatGPT:


Yes, there is a potential test case that could trigger a bug in the program.

The program takes in a number "num" and a base "b", and converts the given number to the given base. One potential bug that could arise is if the input number "num" is negative, as the program does not account for negative numbers.

A test case that could trigger this bug would be to call the function with a negative value for "num" and any positive value for "b". For example, calling the function with inputs to_base(-10, 2) would result in an error as the program does not handle negative numbers. To fix this issue, the program could add a check to ensure that the input number is positive before beginning the conversion process.

request@user:
Give us such test case. Use assert.

response@ChatGPT:
# Test Case 1
# Test the output when num is 0 and base is any positive integer

assert to_base(0, 7) == '0'

# Test Case 2
# Test the output when num is a positive integer and base is 2

assert to_base(15, 2) == '1111'

# Test Case 3
# Test the output when num is a large positive integer and base is 36

assert to_base(123456789, 36) == '21i3v9'

# Test Case 4
# Test the output when num is a negative integer and base is 16

assert to_base(-123, 16) == '-7b'

# Test Case 5
# Test the output when num is floating point number and base is 8
# This should raise a TypeError

try:
    to_base(3.14, 8)
    assert False
except TypeError:
    assert True

