response@ChatGPT:


Yes, there is a test case that can potentially trigger a bug in the program. One such test case could be passing a negative integer or zero as the input argument for the `max` parameter. This could cause the program to enter into an infinite loop since the range function will not generate any values. To prevent this, the program could include a check for non-positive input values and either return an error message or an empty list.

request@user:
Give us such test case. Use assert.

response@ChatGPT:
Here is a test case using assert to ensure that our sieve function correctly returns prime numbers up to 10:

```
def test_sieve():
    expected = [2, 3, 5, 7]
    result = sieve(10)
    assert result == expected, f"Expected {expected}, but got {result}."

test_sieve()
```

This test case asserts that the result of calling sieve(10) is equal to the list [2, 3, 5, 7]. If the result is not equal to the expected value, the assert statement will raise an AssertionError with a message indicating the error.

